Workbook

Sheet README
A1: LandLab-style Simulator - Systems & Flows (v2)
A3: What this is | B3: The full systems catalog for the clone: 168 systems, 797 input/output flows, and 62 resources, with quantities, periods, costs, and labor. A working balance model sits on top, so the Needs Checklist works like the game's results table.
A4: How to use it | B4: Set counts in the yellow "Count in design" column on Systems (a starter design matching the game screenshot is loaded). Then read Needs Checklist and Design Summary. Change climate on Assumptions.
A5: Color key | B5: Yellow fill = cells to edit. Blue text = typed inputs. Green text = formulas tied to Assumptions or another sheet. Black = calculated.
A7: Sheet: Needs Checklist | B7: The game's 11-row results table, driven by the design. Provided vs needed per week, % covered, overall score.
A8: Sheet: Design Summary | B8: Costs, setup labor, weekly labor, land used, days of water and battery storage, weekly cash flow.
A9: Sheet: Systems | B9: One row per system: categories, cost (purchase and DIY), setup and weekly labor, footprint, lifespan, thermal and rain-catchment parameters, and provenance.
A10: Sheet: Flows | B10: THE MODEL TABLE. One row per input or output: quantity, unit (looked up from Resources so every resource has one unit), and period. Weekly-equivalent and design totals are formulas.
A11: Sheet: Resources | B11: Every resource with unit, class (Flow / Capacity / Ambient / Service / Money), its checklist row and conversion factor, and a live weekly balance for the design.
A12: Sheet: Matrix | B12: System x resource grid: IN (blue), OUT (green), I/O (yellow).
A13: Sheet: Categories | B13: The dropdown categories with live counts against the 3-20 target (12-20 for Energy and Shelter).
A14: Sheet: Assumptions | B14: Climate (degree-days, sun, rain, wind) and the period conversion table.
A16: Periods | B16: Each flow has a period: Daily, Weekly, Monthly, Per season, Yearly, One-time, or Capacity. Everything is converted to a weekly average for balancing. One-time flows (setup materials) are excluded from weekly totals. Capacity flows (sq ft of shelter, gallons of tank) are stocks, not consumption, and compare one-to-one.
... A21: Changes from v1 | B21: Categories normalized to the 24 dropdown categories (Plant merged into Plants; Foul renamed Fowl; off-dropdown tags folded in, originals kept in "Original game tags"). New Household category for Human Being.
B22: Game systems with N/A inputs/outputs were filled in (Source says so). Woody Biomass self-loop replaced with a harvest. Sunlight now outputs Sunlight instead of Heat. Green feed merged into Green biomass. Pollen dropped (no consumer). GoSun Cooler outputs Food storage, IBC Tank outputs Water storage, Solar Hot Water Heater outputs Hot water.
B23: Raised Beds recalibrated: the game card shows 8 lbs/week and 100 gal/week from 24 sq ft; realistic intensive yields are ~18 lbs/season and ~15 gal/week.
B24: Labor: the game shows both a Labor input and a separate "weekly maintenance" estimate that disagree. Here weekly upkeep (Systems col K) is added to each system's Labor input automatically.
B25: New resources: Hot water, Greywater, Root crops, Grain, Meat, Milk, Fish, Nuts, Mushrooms, Hay, Gasoline, Propane, Wool, Rainfall, Wind, Stream flow, Water storage, Battery storage, Food storage, Land area, Fenced paddock, Nesting habitat, Pest control.
A27: Known limits | B27: Numbers are rounded rules of thumb (see Confidence column), not engineering sizing. Weekly averages hide seasonality: a garden's output and a stove's fuel use are spread across the year. The balance assumes every system runs at its rated flow; a real engine must curtail systems when inputs run short.
B28: Waste lumber has no on-site producer on purpose: it must be brought in. Several resources are end products (Wool, Wellbeing, storage capacities).

Sheet Needs Checklist
A1: Human Needs Checklist
A2: Humans in design | B2: =SUMIFS(Systems!$R$2:$R$179,Systems!$B$2:$B$179,"Human Being") -> 1
A3: Overall off-grid score | B3: =IFERROR(AVERAGEIF(D6:D16,">0",E6:E16),0) -> 0.48502892
A5: Human need | B5: Unit | C5: Provided by your design (per week) | D5: ="Total system needs for "&B2&" human"&IF(B2=1,"","s")&" (per week)" -> Total system needs for 1 human (per week) | E5: % of need covered | F5: Covered? | G5: Resources that feed this row
A6: Water | B6: gal | C6: =SUMIFS(Flows!$L$2:$L$1500,Flows!$K$2:$K$1500,$A6,Flows!$C$2:$C$1500,"Output") -> 1000 | D6: =SUMIFS(Flows!$L$2:$L$1500,Flows!$K$2:$K$1500,$A6,Flows!$C$2:$C$1500,"Input") -> 151 | E6: =IF(D6=0,0,MIN(1,C6/D6)) -> 1 | F6: =IF(D6=0,"n/a",IF(E6>=1,"✓","✗")) -> ✓ | G6: Water
A7: Drinking water | B7: gal | C7: =SUMIFS(Flows!$L$2:$L$1500,Flows!$K$2:$K$1500,$A7,Flows!$C$2:$C$1500,"Output") -> 0 | D7: =SUMIFS(Flows!$L$2:$L$1500,Flows!$K$2:$K$1500,$A7,Flows!$C$2:$C$1500,"Input") -> 5 | E7: =IF(D7=0,0,MIN(1,C7/D7)) -> 0 | F7: =IF(D7=0,"n/a",IF(E7>=1,"✓","✗")) -> ✗ | G7: Drinking water
A8: Food | B8: kcal | C8: =SUMIFS(Flows!$L$2:$L$1500,Flows!$K$2:$K$1500,$A8,Flows!$C$2:$C$1500,"Output") -> 4978.8462 | D8: =SUMIFS(Flows!$L$2:$L$1500,Flows!$K$2:$K$1500,$A8,Flows!$C$2:$C$1500,"Input") -> 16000 | E8: =IF(D8=0,0,MIN(1,C8/D8)) -> 0.31117788 | F8: =IF(D8=0,"n/a",IF(E8>=1,"✓","✗")) -> ✗ | G8: Food; Vegetables fruit fiber herbs; Root crops; Grain; Eggs; Honey; Meat; Milk; Fish; Nuts; Mushrooms
A9: Shelter | B9: sq ft | C9: =SUMIFS(Flows!$L$2:$L$1500,Flows!$K$2:$K$1500,$A9,Flows!$C$2:$C$1500,"Output") -> 210 | D9: =SUMIFS(Flows!$L$2:$L$1500,Flows!$K$2:$K$1500,$A9,Flows!$C$2:$C$1500,"Input") -> 200 | E9: =IF(D9=0,0,MIN(1,C9/D9)) -> 1 | F9: =IF(D9=0,"n/a",IF(E9>=1,"✓","✗")) -> ✓ | G9: Shelter
A10: Sanitation | B10: lbs | C10: =SUMIFS(Flows!$L$2:$L$1500,Flows!$K$2:$K$1500,$A10,Flows!$C$2:$C$1500,"Output") -> 35 | D10: =SUMIFS(Flows!$L$2:$L$1500,Flows!$K$2:$K$1500,$A10,Flows!$C$2:$C$1500,"Input") -> 17.5 | E10: =IF(D10=0,0,MIN(1,C10/D10)) -> 1 | F10: =IF(D10=0,"n/a",IF(E10>=1,"✓","✗")) -> ✓ | G10: Sanitation
A11: Electricity | B11: kWh | C11: =SUMIFS(Flows!$L$2:$L$1500,Flows!$K$2:$K$1500,$A11,Flows!$C$2:$C$1500,"Output") -> 14 | D11: =SUMIFS(Flows!$L$2:$L$1500,Flows!$K$2:$K$1500,$A11,Flows!$C$2:$C$1500,"Input") -> 24 | E11: =IF(D11=0,0,MIN(1,C11/D11)) -> 0.58333333 | F11: =IF(D11=0,"n/a",IF(E11>=1,"✓","✗")) -> ✗ | G11: Electricity
A12: Transportation | B12: miles | C12: =SUMIFS(Flows!$L$2:$L$1500,Flows!$K$2:$K$1500,$A12,Flows!$C$2:$C$1500,"Output") -> 50 | D12: =SUMIFS(Flows!$L$2:$L$1500,Flows!$K$2:$K$1500,$A12,Flows!$C$2:$C$1500,"Input") -> 150 | E12: =IF(D12=0,0,MIN(1,C12/D12)) -> 0.33333333 | F12: =IF(D12=0,"n/a",IF(E12>=1,"✓","✗")) -> ✗ | G12: Transportation
A13: Cooking fuel | B13: hours | C13: =SUMIFS(Flows!$L$2:$L$1500,Flows!$K$2:$K$1500,$A13,Flows!$C$2:$C$1500,"Output") -> 0 | D13: =SUMIFS(Flows!$L$2:$L$1500,Flows!$K$2:$K$1500,$A13,Flows!$C$2:$C$1500,"Input") -> 5 | E13: =IF(D13=0,0,MIN(1,C13/D13)) -> 0 | F13: =IF(D13=0,"n/a",IF(E13>=1,"✓","✗")) -> ✗ | G13: Cooking fuel
A14: Heated shelter | B14: BTU | C14: =SUMIFS(Flows!$L$2:$L$1500,Flows!$K$2:$K$1500,$A14,Flows!$C$2:$C$1500,"Output") -> 0 | D14: =SUMIFS(Flows!$L$2:$L$1500,Flows!$K$2:$K$1500,$A14,Flows!$C$2:$C$1500,"Input") -> 697846.15 | E14: =IF(D14=0,0,MIN(1,C14/D14)) -> 0 | F14: =IF(D14=0,"n/a",IF(E14>=1,"✓","✗")) -> ✗ | G14: Heat
A15: Cooled shelter | B15: BTU | C15: =SUMIFS(Flows!$L$2:$L$1500,Flows!$K$2:$K$1500,$A15,Flows!$C$2:$C$1500,"Output") -> 10000 | D15: =SUMIFS(Flows!$L$2:$L$1500,Flows!$K$2:$K$1500,$A15,Flows!$C$2:$C$1500,"Input") -> 93046.154 | E15: =IF(D15=0,0,MIN(1,C15/D15)) -> 0.10747354 | F15: =IF(D15=0,"n/a",IF(E15>=1,"✓","✗")) -> ✗ | G15: Cooling
A16: Est. Required Labor | B16: hours | C16: =SUMIFS(Flows!$L$2:$L$1500,Flows!$K$2:$K$1500,$A16,Flows!$C$2:$C$1500,"Output") -> 50 | D16: =SUMIFS(Flows!$L$2:$L$1500,Flows!$K$2:$K$1500,$A16,Flows!$C$2:$C$1500,"Input") -> 9.67 | E16: =IF(D16=0,0,MIN(1,C16/D16)) -> 1 | F16: =IF(D16=0,"n/a",IF(E16>=1,"✓","✗")) -> ✓ | G16: Labor
A18: How it is computed
A19: Provided = every Output flow of that resource family x count in design, converted to the row unit (e.g. lbs of vegetables x 150 kcal). Needed = every Input flow the same way, so animals, gardens, and shelters add to the need alongside people. % = provided / needed, capped at 100%. Overall score = average of rows that have any need.

Sheet Design Summary
A1: Design summary
A2: Everything here updates from the yellow "Count in design" column on Systems.
A4: Metric | B4: Value | C4: Unit | D4: How it is computed
A5: Humans | B5: ='Needs Checklist'!B2 -> 1 | C5: people | D5: Count of Human Being.
A6: Systems placed (excluding people and site) | B6: =SUM(Systems!$R$2:$R$179)-B5-SUMIFS(Systems!$R$2:$R$179,Systems!$C$2:$C$179,"Land",Systems!$L$2:$L$179,0) -> 10 | C6: systems | D6: Sum of counts, minus Human Being and zero-footprint Land systems (Sunlight, Rainfall, etc.).
A7: Overall off-grid score | B7: ='Needs Checklist'!B3 -> 0.48502892 | C7: % | D7: Average coverage across the checklist.
A8: Purchase cost (ready-made) | B8: =SUMPRODUCT(Systems!$G$2:$G$179,Systems!$R$2:$R$179) -> 73110 | C8: $ | D8: Sum of purchase cost x count.
A9: Cheapest build cost | B9: =SUMPRODUCT(Systems!$I$2:$I$179,Systems!$R$2:$R$179) -> 67765 | C9: $ | D9: DIY where offered, otherwise purchase.
A10: Setup labor | B10: =SUMPRODUCT(Systems!$J$2:$J$179,Systems!$R$2:$R$179) -> 123 | C10: hours | D10: One-time build hours.
A11: Labor available per week | B11: ='Needs Checklist'!C16 -> 50 | C11: hours/week | D11: Labor output of Human Being x count.
A12: Labor required per week | B12: ='Needs Checklist'!D16 -> 9.67 | C12: hours/week | D12: All Labor inputs, including upkeep and jobs.
A13: Land available | B13: =SUMIFS(Flows!$J$2:$J$1500,Flows!$D$2:$D$1500,"Land area",Flows!$C$2:$C$1500,"Output") -> 43560 | C13: sq ft | D13: From Land Title or Mortgage.
A14: Land used by footprints | B14: =SUMPRODUCT(Systems!$L$2:$L$179,Systems!$R$2:$R$179) -> 1427 | C14: sq ft | D14: Footprint x count. Roof-mounted systems overlap shelters in reality.
A15: Land used (% of available) | B15: =IF(B13=0,0,B14/B13) -> 0.032759412 | C15: % | D15: Over 100% means the design does not fit.
A16: Water storage | B16: =SUMIFS(Flows!$J$2:$J$1500,Flows!$D$2:$D$1500,"Water storage",Flows!$C$2:$C$1500,"Output") -> 0 | C16: gal | D16: Tanks, cisterns, ponds.
A17: Days of water in storage | B17: =IFERROR(B16/(('Needs Checklist'!D6+'Needs Checklist'!D7)/7),0) -> 0 | C17: days | D17: Storage divided by daily water + drinking-water need.
A18: Battery storage | B18: =SUMIFS(Flows!$J$2:$J$1500,Flows!$D$2:$D$1500,"Battery storage",Flows!$C$2:$C$1500,"Output") -> 0 | C18: kWh | D18: Usable battery capacity.
A19: Days of electricity in batteries | B19: =IFERROR(B18/('Needs Checklist'!D11/7),0) -> 0 | C19: days | D19: Battery kWh divided by daily electricity need.
A20: Food storage | B20: =SUMIFS(Flows!$J$2:$J$1500,Flows!$D$2:$D$1500,"Food storage",Flows!$C$2:$C$1500,"Output") -> 0 | C20: cu ft | D20: Cellar, freezer, canned and dried goods.
A21: Capital in per week | B21: =SUMIFS(Flows!$J$2:$J$1500,Flows!$D$2:$D$1500,"Capital",Flows!$C$2:$C$1500,"Output") -> 0 | C21: $/week | D21: Income from Average Job.
A22: Capital out per week | B22: =SUMIFS(Flows!$J$2:$J$1500,Flows!$D$2:$D$1500,"Capital",Flows!$C$2:$C$1500,"Input") -> 0 | C22: $/week | D22: Running costs of conventional systems.
A23: Net capital per week | B23: =B21-B22 -> 0 | C23: $/week | D23: Negative means the design burns savings.
A24: Wellbeing points per week | B24: =SUMIFS(Flows!$J$2:$J$1500,Flows!$D$2:$D$1500,"Wellbeing",Flows!$C$2:$C$1500,"Output") -> 10 | C24: points | D24: Game-style score.
A25: Resources in deficit | B25: =COUNTIF(Resources!$L$2:$L$64,"Deficit") -> 18 | C25: resources | D25: See Resources, column L.

Sheet Systems
A1: System ID | B1: System | C1: Categories | D1: Original game tags | E1: Source | F1: Description | G1: Purchase cost ($) | H1: DIY cost ($) | I1: Cheapest build ($) | J1: Setup labor (hrs) | K1: Weekly upkeep (hrs) | L1: Footprint (sq ft) | M1: Lifespan (yrs) | N1: Conditioned area (sq ft) | O1: Heat-loss factor (BTU/hr·°F per sq ft) | P1: Catchment area (sq ft) | Q1: Capture efficiency | R1: Count in design | S1: # Inputs | T1: # Outputs | U1: Game-listed inputs | V1: Game-listed outputs | W1: Confidence | X1: Notes
A2: S001 | B2: 2kwh Lead Acid Battery | C2: Energy; Storage | D2: Battery; Energy; Storage | E2: Game (captured) | F2: Deep-cycle lead-acid bank; about 1 kWh usable at 50% depth of discharge. | G2: 450 | H2: 300 | I2: =IF(H2="",G2,MIN(G2,H2)) -> 300 | J2: 2 | K2: 0.1 | L2: 4 | M2: 5 | R2: 0 | S2: =COUNTIFS(Flows!$B$2:$B$1500,$B2,Flows!$C$2:$C$1500,"Input") -> 2 | T2: =COUNTIFS(Flows!$B$2:$B$1500,$B2,Flows!$C$2:$C$1500,"Output") -> 2 | U2: Electricity | V2: Electricity | W2: medium | X2: Stores and returns power with ~80% round-trip efficiency; a net user of electricity.
A3: S002 | B3: 500W Photovoltaic Panels | C3: Energy; Solar | D3: Energy; Solar | E3: Game (captured) | F3: Ground- or roof-mounted 500 W panel set. | G3: 500 | H3: 300 | I3: =IF(H3="",G3,MIN(G3,H3)) -> 300 | J3: 3 | K3: 0.05 | L3: 30 | M3: 25 | R3: 1 | S3: =COUNTIFS(Flows!$B$2:$B$1500,$B3,Flows!$C$2:$C$1500,"Input") -> 2 | T3: =COUNTIFS(Flows!$B$2:$B$1500,$B3,Flows!$C$2:$C$1500,"Output") -> 1 | U3: Sunlight | V3: Electricity | W3: medium
A4: S003 | B4: All Power Labs CHP | C4: Energy; Biomass | D4: Energy; Biomass | E4: Game (captured) | F4: Wood gasifier combined heat and power unit (PP20-class), run ~2 hrs/day. | G4: 35000 | I4: =IF(H4="",G4,MIN(G4,H4)) -> 35000 | J4: 40 | K4: 4 | L4: 100 | M4: 15 | R4: 0 | S4: =COUNTIFS(Flows!$B$2:$B$1500,$B4,Flows!$C$2:$C$1500,"Input") -> 2 | T4: =COUNTIFS(Flows!$B$2:$B$1500,$B4,Flows!$C$2:$C$1500,"Output") -> 3 | U4: Wood pellets | V4: Heat; Biochar; Electricity | W4: low
A5: S004 | B5: Biochar | C5: Biomass; Purification | D5: Energy; Biomass | E5: Game (captured) | F5: Open cone (Kon-Tiki style) kiln that turns brush into biochar. | G5: 400 | H5: 60 | I5: =IF(H5="",G5,MIN(G5,H5)) -> 60 | J5: 2 | K5: 2 | L5: 20 | M5: 10 | R5: 0 | S5: =COUNTIFS(Flows!$B$2:$B$1500,$B5,Flows!$C$2:$C$1500,"Input") -> 3 | T5: =COUNTIFS(Flows!$B$2:$B$1500,$B5,Flows!$C$2:$C$1500,"Output") -> 1 | U5: Woody biomass | V5: Biochar | W5: low | X5: Added quench water. ~15% char yield by mass.
A6: S005 | B6: Biochar Double Barrel Retort | C6: Biomass; Compost | D6: Energy; Compost | E6: Game (captured) | F6: Retort that bakes chips in an inner barrel with an outer fire. | G6: 300 | H6: 80 | I6: =IF(H6="",G6,MIN(G6,H6)) -> 80 | J6: 6 | K6: 2 | L6: 15 | M6: 5 | R6: 0 | S6: =COUNTIFS(Flows!$B$2:$B$1500,$B6,Flows!$C$2:$C$1500,"Input") -> 4 | T6: =COUNTIFS(Flows!$B$2:$B$1500,$B6,Flows!$C$2:$C$1500,"Output") -> 2 | U6: Wood chips; Woody biomass; Waste lumber | V6: Heat; Biochar | W6: low | X6: Heat only counts if the retort sits beside a shelter; entered low.
A7: S006 | B7: A-Frame House | C7: Shelter | D7: Shelter | E7: Game (captured) | F7: Kit-built A-frame, ~800 sq ft conditioned. | G7: 120000 | H7: 55000 | I7: =IF(H7="",G7,MIN(G7,H7)) -> 55000 | J7: 1500 | K7: 1 | L7: 900 | M7: 60 | N7: 800 | O7: 0.3 | R7: 0 | S7: =COUNTIFS(Flows!$B$2:$B$1500,$B7,Flows!$C$2:$C$1500,"Input") -> 4 | T7: =COUNTIFS(Flows!$B$2:$B$1500,$B7,Flows!$C$2:$C$1500,"Output") -> 2 | U7: Capital; Capital | V7: Shelter | W7: medium | X7: Capital = taxes, insurance, upkeep. Duplicate Capital pill merged.
A8: S007 | B8: Average Suburban Home | C8: Shelter; Conventional | D8: Shelter; Conventional | E8: Game (captured) | F8: Median US detached home on city water and sewer. | G8: 420000 | I8: =IF(H8="",G8,MIN(G8,H8)) -> 420000 | J8: 0 | K8: 2 | L8: 2000 | M8: 70 | N8: 2000 | O8: 0.25 | R8: 0 | S8: =COUNTIFS(Flows!$B$2:$B$1500,$B8,Flows!$C$2:$C$1500,"Input") -> 4 | T8: =COUNTIFS(Flows!$B$2:$B$1500,$B8,Flows!$C$2:$C$1500,"Output") -> 6 | U8: Capital; Capital | V8: Sanitation; Drinking water; Water; Roofing area; Shelter | W8: medium | X8: Includes municipal water/sewer and a gas water heater.
A9: S008 | B9: Bell Tent | C9: Shelter; Canvas | D9: Shelter; Canvas | E9: Game (captured) | F9: 5 m canvas bell tent (~210 sq ft). | G9: 800 | H9: 300 | I9: =IF(H9="",G9,MIN(G9,H9)) -> 300 | J9: 3 | K9: 0.25 | L9: 210 | M9: 5 | N9: 210 | O9: 1.2 | R9: 1 | S9: =COUNTIFS(Flows!$B$2:$B$1500,$B9,Flows!$C$2:$C$1500,"Input") -> 3 | T9: =COUNTIFS(Flows!$B$2:$B$1500,$B9,Flows!$C$2:$C$1500,"Output") -> 1 | U9: Labor | V9: Shelter | W9: medium
A10: S009 | B10: Camp 365 Off-Grid Camper | C10: Shelter; Transportation | D10: Shelter; Transportation | E10: Game (captured) | F10: Towable off-grid camper; needs a tow vehicle to move. | G10: 65000 | I10: =IF(H10="",G10,MIN(G10,H10)) -> 65000 | J10: 2 | K10: 0.5 | L10: 150 | M10: 20 | N10: 150 | O10: 0.6 | R10: 0 | S10: =COUNTIFS(Flows!$B$2:$B$1500,$B10,Flows!$C$2:$C$1500,"Input") -> 4 | T10: =COUNTIFS(Flows!$B$2:$B$1500,$B10,Flows!$C$2:$C$1500,"Output") -> 2 | U10: Capital; Labor | V10: Shelter | W10: low
A11: S010 | B11: Camper Van | C11: Transportation; Shelter | D11: Transportation; Shelter | E11: Game (captured) | F11: Converted cargo van; home and vehicle in one. | G11: 80000 | H11: 25000 | I11: =IF(H11="",G11,MIN(G11,H11)) -> 25000 | J11: 300 | K11: 1 | L11: 80 | M11: 15 | N11: 60 | O11: 0.8 | R11: 0 | S11: =COUNTIFS(Flows!$B$2:$B$1500,$B11,Flows!$C$2:$C$1500,"Input") -> 5 | T11: =COUNTIFS(Flows!$B$2:$B$1500,$B11,Flows!$C$2:$C$1500,"Output") -> 2 | U11: Capital; Capital | V11: Shelter; Transportation | W11: low
A12: S011 | B12: Green Biomass | C12: Biomass | D12: Biomass; Nitrogen | E12: Game (captured) | F12: Cut-and-carry greens patch (comfrey, alfalfa, weeds), ~400 sq ft. | G12: 50 | H12: 20 | I12: =IF(H12="",G12,MIN(G12,H12)) -> 20 | J12: 4 | K12: 1.5 | L12: 400 | M12: 10 | R12: 0 | S12: =COUNTIFS(Flows!$B$2:$B$1500,$B12,Flows!$C$2:$C$1500,"Input") -> 3 | T12: =COUNTIFS(Flows!$B$2:$B$1500,$B12,Flows!$C$2:$C$1500,"Output") -> 1 | U12: Labor | V12: Green biomass | W12: low
A13: S012 | B13: Woody Biomass | C13: Biomass | D13: Biomass | E13: Game (captured) | F13: Brush and deadfall harvest with a splitting station. | G13: 150 | H13: 50 | I13: =IF(H13="",G13,MIN(G13,H13)) -> 50 | J13: 4 | K13: 3 | L13: 50 | M13: 20 | R13: 0 | S13: =COUNTIFS(Flows!$B$2:$B$1500,$B13,Flows!$C$2:$C$1500,"Input") -> 1 | T13: =COUNTIFS(Flows!$B$2:$B$1500,$B13,Flows!$C$2:$C$1500,"Output") -> 1 | U13: Woody biomass | V13: Woody biomass | W13: low | X13: Game loops Woody biomass to itself; redefined as a harvest from existing woods (labor in, wood out).
A14: S013 | B14: Firepit | C14: Cooking; Heating | D14: Energy; Biomass | E14: Game (captured) | F14: Outdoor stone firepit. | G14: 300 | H14: 50 | I14: =IF(H14="",G14,MIN(G14,H14)) -> 50 | J14: 2 | K14: 0.5 | L14: 30 | M14: 15 | R14: 0 | S14: =COUNTIFS(Flows!$B$2:$B$1500,$B14,Flows!$C$2:$C$1500,"Input") -> 2 | T14: =COUNTIFS(Flows!$B$2:$B$1500,$B14,Flows!$C$2:$C$1500,"Output") -> 3 | U14: Woody biomass | V14: Cooking fuel; Heat | W14: low | X14: Outdoor heat entered low; it does not warm a shelter.
A15: S014 | B15: Livestock Guardian Dog | C15: Livestock | D15: Pet | E15: Game (captured) | F15: Working guardian dog for poultry and goats. | G15: 1500 | I15: =IF(H15="",G15,MIN(G15,H15)) -> 1500 | J15: 20 | K15: 3.5 | L15: 0 | M15: 10 | R15: 0 | S15: =COUNTIFS(Flows!$B$2:$B$1500,$B15,Flows!$C$2:$C$1500,"Input") -> 3 | T15: =COUNTIFS(Flows!$B$2:$B$1500,$B15,Flows!$C$2:$C$1500,"Output") -> 3 | U15: Water; Food | V15: Organic waste; Wellbeing | W15: low
A16: S015 | B16: Baby Chicks | C16: Livestock; Fowl | D16: Livestock; Foul | E16: Game (captured) | F16: Batch of 12 chicks for their first 8 weeks. | G16: 100 | I16: =IF(H16="",G16,MIN(G16,H16)) -> 100 | J16: 3 | K16: 1 | L16: 20 | M16: 0.15 | R16: 0 | S16: =COUNTIFS(Flows!$B$2:$B$1500,$B16,Flows!$C$2:$C$1500,"Input") -> 3 | T16: =COUNTIFS(Flows!$B$2:$B$1500,$B16,Flows!$C$2:$C$1500,"Output") -> 1 | U16: Water; Chicken feed | V16: Manure | W16: low
A17: S016 | B17: Beehive + Bee Colony | C17: Livestock; Insects | D17: Livestock; Insects | E17: Game (captured) | F17: Langstroth hive with one colony. | G17: 500 | H17: 200 | I17: =IF(H17="",G17,MIN(G17,H17)) -> 200 | J17: 6 | K17: 0.5 | L17: 10 | M17: 10 | R17: 0 | S17: =COUNTIFS(Flows!$B$2:$B$1500,$B17,Flows!$C$2:$C$1500,"Input") -> 3 | T17: =COUNTIFS(Flows!$B$2:$B$1500,$B17,Flows!$C$2:$C$1500,"Output") -> 2 | U17: Pollinator flowers; Water | V17: Honey; Pollination; Pollen | W17: low | X17: Pollen output dropped (no consumer); honey ~40 lbs/yr harvestable.
A18: S017 | B18: Black Soldier Fly Protopod (BSF) | C18: Insects; Compost | D18: Livestock; Insects | E18: Game (captured) | F18: Self-harvesting BSF larva bin. | G18: 180 | H18: 60 | I18: =IF(H18="",G18,MIN(G18,H18)) -> 60 | J18: 2 | K18: 0.5 | L18: 6 | M18: 5 | R18: 0 | S18: =COUNTIFS(Flows!$B$2:$B$1500,$B18,Flows!$C$2:$C$1500,"Input") -> 3 | T18: =COUNTIFS(Flows!$B$2:$B$1500,$B18,Flows!$C$2:$C$1500,"Output") -> 2 | U18: Coffee grounds; Food waste | V18: Manure; Grubs | W18: low
A19: S018 | B19: Chicken | C19: Livestock; Fowl | D19: Livestock; Foul | E19: Game (captured) | F19: A single laying hen. | G19: 25 | I19: =IF(H19="",G19,MIN(G19,H19)) -> 25 | J19: 0.5 | K19: 0.15 | L19: 10 | M19: 5 | R19: 0 | S19: =COUNTIFS(Flows!$B$2:$B$1500,$B19,Flows!$C$2:$C$1500,"Input") -> 6 | T19: =COUNTIFS(Flows!$B$2:$B$1500,$B19,Flows!$C$2:$C$1500,"Output") -> 2 | U19: Green biomass; Grubs; Food waste; Water | V19: Manure; Eggs | W19: medium | X19: Added bagged feed; free-range forage alone rarely sustains laying.
A20: S019 | B20: Aptera Electric Vehicle (Solar Charge) | C20: Transportation; Solar | D20: Transportation; Solar | E20: Game (captured) | F20: Three-wheel solar EV with grid top-up. | G20: 33000 | I20: =IF(H20="",G20,MIN(G20,H20)) -> 33000 | J20: 1 | K20: 0.1 | L20: 100 | M20: 15 | R20: 0 | S20: =COUNTIFS(Flows!$B$2:$B$1500,$B20,Flows!$C$2:$C$1500,"Input") -> 4 | T20: =COUNTIFS(Flows!$B$2:$B$1500,$B20,Flows!$C$2:$C$1500,"Output") -> 1 | U20: Sunlight; Capital | V20: Transportation | W20: low
A21: S020 | B21: Average American Vehicle | C21: Transportation; Conventional | D21: Transportation; Conventional | E21: Game (captured) | F21: Gasoline sedan, ~13,000 miles/yr. | G21: 48000 | I21: =IF(H21="",G21,MIN(G21,H21)) -> 48000 | J21: 1 | K21: 0.2 | L21: 150 | M21: 12 | R21: 0 | S21: =COUNTIFS(Flows!$B$2:$B$1500,$B21,Flows!$C$2:$C$1500,"Input") -> 3 | T21: =COUNTIFS(Flows!$B$2:$B$1500,$B21,Flows!$C$2:$C$1500,"Output") -> 1 | U21: Capital | V21: Transportation | W21: medium | X21: Capital = insurance, repairs, depreciation (fuel separate).
A22: S021 | B22: Bike | C22: Transportation | D22: Transportation | E22: Game (captured) | F22: Commuter bicycle. | G22: 600 | H22: 150 | I22: =IF(H22="",G22,MIN(G22,H22)) -> 150 | J22: 1 | K22: 0.2 | L22: 10 | M22: 10 | R22: 0 | S22: =COUNTIFS(Flows!$B$2:$B$1500,$B22,Flows!$C$2:$C$1500,"Input") -> 3 | T22: =COUNTIFS(Flows!$B$2:$B$1500,$B22,Flows!$C$2:$C$1500,"Output") -> 2 | U22: Labor | V22: Wellbeing; Transportation | W22: medium | X22: Riding time counts as labor; ~40 kcal/mile of rider food.
A23: S022 | B23: Drinking Water Filter | C23: Water-System; Purification | D23: Water-System; Purification | E23: Game (captured) | F23: Gravity ceramic/carbon filter (Berkey-type). | G23: 350 | I23: =IF(H23="",G23,MIN(G23,H23)) -> 350 | J23: 0.5 | K23: 0.25 | L23: 2 | M23: 10 | R23: 0 | S23: =COUNTIFS(Flows!$B$2:$B$1500,$B23,Flows!$C$2:$C$1500,"Input") -> 2 | T23: =COUNTIFS(Flows!$B$2:$B$1500,$B23,Flows!$C$2:$C$1500,"Output") -> 1 | U23: Labor; Water | V23: Drinking water | W23: medium
A24: S023 | B24: GoSun Water Filter | C24: Water-System; Purification | D24: Water-System; Purification | E24: Game (captured) | F24: Solar pasteurizing water flask. | G24: 150 | I24: =IF(H24="",G24,MIN(G24,H24)) -> 150 | J24: 0.25 | K24: 0.1 | L24: 2 | M24: 5 | R24: 0 | S24: =COUNTIFS(Flows!$B$2:$B$1500,$B24,Flows!$C$2:$C$1500,"Input") -> 3 | T24: =COUNTIFS(Flows!$B$2:$B$1500,$B24,Flows!$C$2:$C$1500,"Output") -> 1 | U24: Water | V24: Drinking water | W24: low
A25: S024 | B25: Rainwater Collection System + Cistern (550 Gallons) | C25: Water-System; Storage | D25: Water-System; Storage | E25: Game (captured) | F25: Gutters, first-flush diverter, and a 550-gal cistern. | G25: 1200 | H25: 500 | I25: =IF(H25="",G25,MIN(G25,H25)) -> 500 | J25: 12 | K25: 0.25 | L25: 20 | M25: 20 | P25: 1000 | Q25: 0.8 | R25: 0 | S25: =COUNTIFS(Flows!$B$2:$B$1500,$B25,Flows!$C$2:$C$1500,"Input") -> 3 | T25: =COUNTIFS(Flows!$B$2:$B$1500,$B25,Flows!$C$2:$C$1500,"Output") -> 2 | U25: Roofing area | V25: Water | W25: medium | X25: Water out = catchment x rainfall x 0.623 gal/sq ft-in x efficiency. Catchment must be covered by Roofing area.
A26: S025 | B26: Solar Hot Water Heater | C26: Solar; Water-System; Heating | D26: Solar; Water-System; Heating | E26: Game (captured) | F26: Flat-plate solar collector with storage tank. | G26: 4500 | H26: 1500 | I26: =IF(H26="",G26,MIN(G26,H26)) -> 1500 | J26: 16 | K26: 0.1 | L26: 40 | M26: 20 | R26: 0 | S26: =COUNTIFS(Flows!$B$2:$B$1500,$B26,Flows!$C$2:$C$1500,"Input") -> 3 | T26: =COUNTIFS(Flows!$B$2:$B$1500,$B26,Flows!$C$2:$C$1500,"Output") -> 1 | U26: Water | V26: Water | W26: low | X26: Output changed from Water to Hot water.
A27: S026 | B27: WaterDrop Water Filter | C27: Purification; Water-System | D27: Purification; Water-System | E27: Game (captured) | F27: Under-sink tankless reverse-osmosis filter. | G27: 300 | I27: =IF(H27="",G27,MIN(G27,H27)) -> 300 | J27: 1 | K27: 0.1 | L27: 2 | M27: 5 | R27: 0 | S27: =COUNTIFS(Flows!$B$2:$B$1500,$B27,Flows!$C$2:$C$1500,"Input") -> 3 | T27: =COUNTIFS(Flows!$B$2:$B$1500,$B27,Flows!$C$2:$C$1500,"Output") -> 2 | U27: Labor; Water | V27: Drinking water | W27: low | X27: RO rejects about half its input.
A28: S027 | B28: Average Job | C28: Conventional | D28: Conventional | E28: Game (captured) | F28: Full-time job at US median weekly earnings. | G28: 0 | I28: =IF(H28="",G28,MIN(G28,H28)) -> 0 | J28: 0 | K28: 0 | L28: 0 | M28: 40 | R28: 0 | S28: =COUNTIFS(Flows!$B$2:$B$1500,$B28,Flows!$C$2:$C$1500,"Input") -> 2 | T28: =COUNTIFS(Flows!$B$2:$B$1500,$B28,Flows!$C$2:$C$1500,"Output") -> 1 | U28: Labor | V28: Capital | W28: medium | X28: Commute of ~30 miles/day added.
A29: S028 | B29: Big Box Grocery Store | C29: Conventional; Food System | D29: Conventional; Food System | E29: Game (captured) | F29: Groceries for one person for a week. | G29: 0 | I29: =IF(H29="",G29,MIN(G29,H29)) -> 0 | J29: 0 | K29: 0 | L29: 0 | M29: 1 | R29: 0 | S29: =COUNTIFS(Flows!$B$2:$B$1500,$B29,Flows!$C$2:$C$1500,"Input") -> 2 | T29: =COUNTIFS(Flows!$B$2:$B$1500,$B29,Flows!$C$2:$C$1500,"Output") -> 2 | U29: Capital | V29: Food | W29: medium
A30: S029 | B30: Central Power Plant (Coal / NatGas / Nuclear) | C30: Energy; Conventional | D30: Energy; Conventional | E30: Game (captured) | F30: Utility electric and gas service for one home. | G30: 2500 | I30: =IF(H30="",G30,MIN(G30,H30)) -> 2500 | J30: 4 | K30: 0 | L30: 0 | M30: 50 | R30: 0 | S30: =COUNTIFS(Flows!$B$2:$B$1500,$B30,Flows!$C$2:$C$1500,"Input") -> 1 | T30: =COUNTIFS(Flows!$B$2:$B$1500,$B30,Flows!$C$2:$C$1500,"Output") -> 4 | U30: Capital | V30: Heat; Cooking fuel; Cooling; Electricity | W30: medium | X30: Purchase cost = connection fee.
A31: S030 | B31: Factory Farmed Food (Family of Four) | C31: Conventional; Food System | D31: Conventional; Food System | E31: Game (captured; empty I/O filled in) | F31: Industrial food supply for four people. | G31: 0 | I31: =IF(H31="",G31,MIN(G31,H31)) -> 0 | J31: 0 | K31: 0 | L31: 0 | M31: 1 | R31: 0 | S31: =COUNTIFS(Flows!$B$2:$B$1500,$B31,Flows!$C$2:$C$1500,"Input") -> 2 | T31: =COUNTIFS(Flows!$B$2:$B$1500,$B31,Flows!$C$2:$C$1500,"Output") -> 2 | U31: N/A | V31: N/A | W31: low
A32: S031 | B32: Food Waste | C32: Compost | D32: Food-Waste | E32: Game (captured) | F32: Weekly scrap pickup from neighbors and a cafe. | G32: 0 | I32: =IF(H32="",G32,MIN(G32,H32)) -> 0 | J32: 0 | K32: 0.5 | L32: 0 | M32: 1 | R32: 0 | S32: =COUNTIFS(Flows!$B$2:$B$1500,$B32,Flows!$C$2:$C$1500,"Input") -> 2 | T32: =COUNTIFS(Flows!$B$2:$B$1500,$B32,Flows!$C$2:$C$1500,"Output") -> 2 | U32: Transportation | V32: Food waste | W32: low
A33: S032 | B33: IBC Tank (food grade) | C33: Water-System; Storage | D33: Water-System; Storage | E33: Game (captured) | F33: 275-gal food-grade tote. | G33: 150 | I33: =IF(H33="",G33,MIN(G33,H33)) -> 150 | J33: 1 | K33: 0.05 | L33: 16 | M33: 10 | R33: 0 | S33: =COUNTIFS(Flows!$B$2:$B$1500,$B33,Flows!$C$2:$C$1500,"Input") -> 1 | T33: =COUNTIFS(Flows!$B$2:$B$1500,$B33,Flows!$C$2:$C$1500,"Output") -> 1 | U33: N/A | V33: Storage space | W33: medium | X33: Output changed to Water storage.
A34: S033 | B34: Permaculture Food Forest (1/4 acre) | C34: Food System; Plants | D34: Food System; Plants | E34: Game (captured) | F34: Layered fruit, nut, and perennial planting at maturity. | G34: 8000 | H34: 2500 | I34: =IF(H34="",G34,MIN(G34,H34)) -> 2500 | J34: 120 | K34: 3 | L34: 10890 | M34: 40 | R34: 0 | S34: =COUNTIFS(Flows!$B$2:$B$1500,$B34,Flows!$C$2:$C$1500,"Input") -> 5 | T34: =COUNTIFS(Flows!$B$2:$B$1500,$B34,Flows!$C$2:$C$1500,"Output") -> 4 | U34: Seedlings; Water; Compost; Pollination; Labor | V34: Wellbeing; Pollinator flowers; Vegetables fruit fiber herbs | W34: low | X34: Yields are for a mature forest (year 7+).
A35: S034 | B35: Composting Outhouse | C35: Sanitation | D35: Sanitation | E35: Game (captured) | F35: Two-chamber composting outhouse. | G35: 1500 | H35: 500 | I35: =IF(H35="",G35,MIN(G35,H35)) -> 500 | J35: 30 | K35: 0.5 | L35: 30 | M35: 20 | R35: 1 | S35: =COUNTIFS(Flows!$B$2:$B$1500,$B35,Flows!$C$2:$C$1500,"Input") -> 3 | T35: =COUNTIFS(Flows!$B$2:$B$1500,$B35,Flows!$C$2:$C$1500,"Output") -> 2 | U35: Organic waste | V35: Sanitation | W35: medium | X35: Sized for two people.
A36: S035 | B36: Compost Piles | C36: Compost; Garden; Sanitation | D36: Compost; Garden; Sanitation | E36: Game (captured) | F36: Three-bin hot compost system. | G36: 100 | H36: 0 | I36: =IF(H36="",G36,MIN(G36,H36)) -> 0 | J36: 4 | K36: 1 | L36: 50 | M36: 10 | R36: 1 | S36: =COUNTIFS(Flows!$B$2:$B$1500,$B36,Flows!$C$2:$C$1500,"Input") -> 5 | T36: =COUNTIFS(Flows!$B$2:$B$1500,$B36,Flows!$C$2:$C$1500,"Output") -> 1 | U36: Water; Green biomass; Carbon; Biochar | V36: Compost | W36: medium
A37: S036 | B37: Compost Roller | C37: Compost; Tools | D37: Compost; Tools | E37: Game (captured) | F37: Tumbling compost drum. | G37: 250 | H37: 80 | I37: =IF(H37="",G37,MIN(G37,H37)) -> 80 | J37: 1 | K37: 0.5 | L37: 10 | M37: 8 | R37: 0 | S37: =COUNTIFS(Flows!$B$2:$B$1500,$B37,Flows!$C$2:$C$1500,"Input") -> 4 | T37: =COUNTIFS(Flows!$B$2:$B$1500,$B37,Flows!$C$2:$C$1500,"Output") -> 1 | U37: Labor; Water; Green biomass; Carbon | V37: Compost | W37: low
A38: S037 | B38: Compost Toilet | C38: Sanitation; Compost | D38: Sanitation; Toilet; Compost | E38: Game (captured) | F38: Self-contained urine-diverting toilet (one person). | G38: 1000 | H38: 300 | I38: =IF(H38="",G38,MIN(G38,H38)) -> 300 | J38: 4 | K38: 0.5 | L38: 10 | M38: 15 | R38: 0 | S38: =COUNTIFS(Flows!$B$2:$B$1500,$B38,Flows!$C$2:$C$1500,"Input") -> 4 | T38: =COUNTIFS(Flows!$B$2:$B$1500,$B38,Flows!$C$2:$C$1500,"Output") -> 3 | U38: Organic waste | V38: Sanitation; Liquid fertilizer; Compost | W38: medium
A39: S038 | B39: Throne Composting Toilet | C39: Sanitation | D39: Sanitation; Toilet | E39: Game (captured) | F39: Premium composting toilet (one person). | G39: 1400 | I39: =IF(H39="",G39,MIN(G39,H39)) -> 1400 | J39: 4 | K39: 0.5 | L39: 10 | M39: 15 | R39: 0 | S39: =COUNTIFS(Flows!$B$2:$B$1500,$B39,Flows!$C$2:$C$1500,"Input") -> 4 | T39: =COUNTIFS(Flows!$B$2:$B$1500,$B39,Flows!$C$2:$C$1500,"Output") -> 2 | U39: Organic waste | V39: Sanitation | W39: low
A40: S039 | B40: GoSun Solar Oven | C40: Cooking; Solar | D40: Cooking; Solar | E40: Game (captured) | F40: Evacuated-tube solar cooker. | G40: 350 | H40: 100 | I40: =IF(H40="",G40,MIN(G40,H40)) -> 100 | J40: 0.25 | K40: 0.1 | L40: 4 | M40: 8 | R40: 0 | S40: =COUNTIFS(Flows!$B$2:$B$1500,$B40,Flows!$C$2:$C$1500,"Input") -> 2 | T40: =COUNTIFS(Flows!$B$2:$B$1500,$B40,Flows!$C$2:$C$1500,"Output") -> 1 | U40: Sunlight | V40: Cooking fuel | W40: medium
...

Sheet Flows
A1: Flow ID | B1: System | C1: Direction | D1: Resource | E1: Qty per period | F1: Unit | G1: Period | H1: Weekly equivalent (per unit) | I1: Count in design | J1: Weekly total (design) | K1: Needs Checklist row | L1: Contribution to need | M1: Key | N1: Notes
A2: F0001 | B2: 2kwh Lead Acid Battery | C2: Input | D2: Labor | E2: 0.1 | F2: =IFERROR(INDEX(Resources!$B$2:$B$64,MATCH($D2,Resources!$A$2:$A$64,0)),"?") -> hours | G2: Weekly | H2: =E2*INDEX(Assumptions!$D$17:$D$23,MATCH(G2,Assumptions!$B$17:$B$23,0)) -> 0.1 | I2: =IFERROR(INDEX(Systems!$R$2:$R$179,MATCH($B2,Systems!$B$2:$B$179,0)),0) -> 0 | J2: =H2*I2 -> 0 | K2: =IFERROR(IF(INDEX(Resources!$D$2:$D$64,MATCH($D2,Resources!$A$2:$A$64,0))="","",INDEX(Resources!$D$2:$D$64,MATCH($D2,Resources!$A$2:$A$64,0))),"") -> Est. Required Labor | L2: =IF(K2="","",J2*INDEX(Resources!$E$2:$E$64,MATCH($D2,Resources!$A$2:$A$64,0))) -> 0 | M2: =B2&"|"&D2&"|"&C2 -> 2kwh Lead Acid Battery|Labor|Input | N2: Weekly upkeep hours (Systems column K).
A3: F0002 | B3: 2kwh Lead Acid Battery | C3: Input | D3: Electricity | E3: 8.75 | F3: =IFERROR(INDEX(Resources!$B$2:$B$64,MATCH($D3,Resources!$A$2:$A$64,0)),"?") -> kWh | G3: Weekly | H3: =E3*INDEX(Assumptions!$D$17:$D$23,MATCH(G3,Assumptions!$B$17:$B$23,0)) -> 8.75 | I3: =IFERROR(INDEX(Systems!$R$2:$R$179,MATCH($B3,Systems!$B$2:$B$179,0)),0) -> 0 | J3: =H3*I3 -> 0 | K3: =IFERROR(IF(INDEX(Resources!$D$2:$D$64,MATCH($D3,Resources!$A$2:$A$64,0))="","",INDEX(Resources!$D$2:$D$64,MATCH($D3,Resources!$A$2:$A$64,0))),"") -> Electricity | L3: =IF(K3="","",J3*INDEX(Resources!$E$2:$E$64,MATCH($D3,Resources!$A$2:$A$64,0))) -> 0 | M3: =B3&"|"&D3&"|"&C3 -> 2kwh Lead Acid Battery|Electricity|Input
A4: F0003 | B4: 2kwh Lead Acid Battery | C4: Output | D4: Electricity | E4: 7 | F4: =IFERROR(INDEX(Resources!$B$2:$B$64,MATCH($D4,Resources!$A$2:$A$64,0)),"?") -> kWh | G4: Weekly | H4: =E4*INDEX(Assumptions!$D$17:$D$23,MATCH(G4,Assumptions!$B$17:$B$23,0)) -> 7 | I4: =IFERROR(INDEX(Systems!$R$2:$R$179,MATCH($B4,Systems!$B$2:$B$179,0)),0) -> 0 | J4: =H4*I4 -> 0 | K4: =IFERROR(IF(INDEX(Resources!$D$2:$D$64,MATCH($D4,Resources!$A$2:$A$64,0))="","",INDEX(Resources!$D$2:$D$64,MATCH($D4,Resources!$A$2:$A$64,0))),"") -> Electricity | L4: =IF(K4="","",J4*INDEX(Resources!$E$2:$E$64,MATCH($D4,Resources!$A$2:$A$64,0))) -> 0 | M4: =B4&"|"&D4&"|"&C4 -> 2kwh Lead Acid Battery|Electricity|Output
A5: F0004 | B5: 2kwh Lead Acid Battery | C5: Output | D5: Battery storage | E5: 1 | F5: =IFERROR(INDEX(Resources!$B$2:$B$64,MATCH($D5,Resources!$A$2:$A$64,0)),"?") -> kWh | G5: Capacity | H5: =E5*INDEX(Assumptions!$D$17:$D$23,MATCH(G5,Assumptions!$B$17:$B$23,0)) -> 1 | I5: =IFERROR(INDEX(Systems!$R$2:$R$179,MATCH($B5,Systems!$B$2:$B$179,0)),0) -> 0 | J5: =H5*I5 -> 0 | K5: =IFERROR(IF(INDEX(Resources!$D$2:$D$64,MATCH($D5,Resources!$A$2:$A$64,0))="","",INDEX(Resources!$D$2:$D$64,MATCH($D5,Resources!$A$2:$A$64,0))),"") | L5: =IF(K5="","",J5*INDEX(Resources!$E$2:$E$64,MATCH($D5,Resources!$A$2:$A$64,0))) | M5: =B5&"|"&D5&"|"&C5 -> 2kwh Lead Acid Battery|Battery storage|Output
A6: F0005 | B6: 500W Photovoltaic Panels | C6: Input | D6: Labor | E6: 0.05 | F6: =IFERROR(INDEX(Resources!$B$2:$B$64,MATCH($D6,Resources!$A$2:$A$64,0)),"?") -> hours | G6: Weekly | H6: =E6*INDEX(Assumptions!$D$17:$D$23,MATCH(G6,Assumptions!$B$17:$B$23,0)) -> 0.05 | I6: =IFERROR(INDEX(Systems!$R$2:$R$179,MATCH($B6,Systems!$B$2:$B$179,0)),0) -> 1 | J6: =H6*I6 -> 0.05 | K6: =IFERROR(IF(INDEX(Resources!$D$2:$D$64,MATCH($D6,Resources!$A$2:$A$64,0))="","",INDEX(Resources!$D$2:$D$64,MATCH($D6,Resources!$A$2:$A$64,0))),"") -> Est. Required Labor | L6: =IF(K6="","",J6*INDEX(Resources!$E$2:$E$64,MATCH($D6,Resources!$A$2:$A$64,0))) -> 0.05 | M6: =B6&"|"&D6&"|"&C6 -> 500W Photovoltaic Panels|Labor|Input | N6: Weekly upkeep hours (Systems column K).
A7: F0006 | B7: 500W Photovoltaic Panels | C7: Input | D7: Sunlight | E7: =Assumptions!$C$6*7 -> 35 | F7: =IFERROR(INDEX(Resources!$B$2:$B$64,MATCH($D7,Resources!$A$2:$A$64,0)),"?") -> sun-hours | G7: Weekly | H7: =E7*INDEX(Assumptions!$D$17:$D$23,MATCH(G7,Assumptions!$B$17:$B$23,0)) -> 35 | I7: =IFERROR(INDEX(Systems!$R$2:$R$179,MATCH($B7,Systems!$B$2:$B$179,0)),0) -> 1 | J7: =H7*I7 -> 35 | K7: =IFERROR(IF(INDEX(Resources!$D$2:$D$64,MATCH($D7,Resources!$A$2:$A$64,0))="","",INDEX(Resources!$D$2:$D$64,MATCH($D7,Resources!$A$2:$A$64,0))),"") | L7: =IF(K7="","",J7*INDEX(Resources!$E$2:$E$64,MATCH($D7,Resources!$A$2:$A$64,0))) | M7: =B7&"|"&D7&"|"&C7 -> 500W Photovoltaic Panels|Sunlight|Input | N7: Sun-hours per week from Assumptions.
A8: F0007 | B8: 500W Photovoltaic Panels | C8: Output | D8: Electricity | E8: =0.5*Assumptions!$C$6*7*Assumptions!$C$7 -> 14 | F8: =IFERROR(INDEX(Resources!$B$2:$B$64,MATCH($D8,Resources!$A$2:$A$64,0)),"?") -> kWh | G8: Weekly | H8: =E8*INDEX(Assumptions!$D$17:$D$23,MATCH(G8,Assumptions!$B$17:$B$23,0)) -> 14 | I8: =IFERROR(INDEX(Systems!$R$2:$R$179,MATCH($B8,Systems!$B$2:$B$179,0)),0) -> 1 | J8: =H8*I8 -> 14 | K8: =IFERROR(IF(INDEX(Resources!$D$2:$D$64,MATCH($D8,Resources!$A$2:$A$64,0))="","",INDEX(Resources!$D$2:$D$64,MATCH($D8,Resources!$A$2:$A$64,0))),"") -> Electricity | L8: =IF(K8="","",J8*INDEX(Resources!$E$2:$E$64,MATCH($D8,Resources!$A$2:$A$64,0))) -> 14 | M8: =B8&"|"&D8&"|"&C8 -> 500W Photovoltaic Panels|Electricity|Output | N8: 0.5 kW rating x sun-hours x derate.
A9: F0008 | B9: All Power Labs CHP | C9: Input | D9: Labor | E9: 4 | F9: =IFERROR(INDEX(Resources!$B$2:$B$64,MATCH($D9,Resources!$A$2:$A$64,0)),"?") -> hours | G9: Weekly | H9: =E9*INDEX(Assumptions!$D$17:$D$23,MATCH(G9,Assumptions!$B$17:$B$23,0)) -> 4 | I9: =IFERROR(INDEX(Systems!$R$2:$R$179,MATCH($B9,Systems!$B$2:$B$179,0)),0) -> 0 | J9: =H9*I9 -> 0 | K9: =IFERROR(IF(INDEX(Resources!$D$2:$D$64,MATCH($D9,Resources!$A$2:$A$64,0))="","",INDEX(Resources!$D$2:$D$64,MATCH($D9,Resources!$A$2:$A$64,0))),"") -> Est. Required Labor | L9: =IF(K9="","",J9*INDEX(Resources!$E$2:$E$64,MATCH($D9,Resources!$A$2:$A$64,0))) -> 0 | M9: =B9&"|"&D9&"|"&C9 -> All Power Labs CHP|Labor|Input | N9: Weekly upkeep hours (Systems column K).
A10: F0009 | B10: All Power Labs CHP | C10: Input | D10: Wood pellets | E10: 370 | F10: =IFERROR(INDEX(Resources!$B$2:$B$64,MATCH($D10,Resources!$A$2:$A$64,0)),"?") -> lbs | G10: Weekly | H10: =E10*INDEX(Assumptions!$D$17:$D$23,MATCH(G10,Assumptions!$B$17:$B$23,0)) -> 370 | I10: =IFERROR(INDEX(Systems!$R$2:$R$179,MATCH($B10,Systems!$B$2:$B$179,0)),0) -> 0 | J10: =H10*I10 -> 0 | K10: =IFERROR(IF(INDEX(Resources!$D$2:$D$64,MATCH($D10,Resources!$A$2:$A$64,0))="","",INDEX(Resources!$D$2:$D$64,MATCH($D10,Resources!$A$2:$A$64,0))),"") | L10: =IF(K10="","",J10*INDEX(Resources!$E$2:$E$64,MATCH($D10,Resources!$A$2:$A$64,0))) | M10: =B10&"|"&D10&"|"&C10 -> All Power Labs CHP|Wood pellets|Input
A11: F0010 | B11: All Power Labs CHP | C11: Output | D11: Electricity | E11: 140 | F11: =IFERROR(INDEX(Resources!$B$2:$B$64,MATCH($D11,Resources!$A$2:$A$64,0)),"?") -> kWh | G11: Weekly | H11: =E11*INDEX(Assumptions!$D$17:$D$23,MATCH(G11,Assumptions!$B$17:$B$23,0)) -> 140 | I11: =IFERROR(INDEX(Systems!$R$2:$R$179,MATCH($B11,Systems!$B$2:$B$179,0)),0) -> 0 | J11: =H11*I11 -> 0 | K11: =IFERROR(IF(INDEX(Resources!$D$2:$D$64,MATCH($D11,Resources!$A$2:$A$64,0))="","",INDEX(Resources!$D$2:$D$64,MATCH($D11,Resources!$A$2:$A$64,0))),"") -> Electricity | L11: =IF(K11="","",J11*INDEX(Resources!$E$2:$E$64,MATCH($D11,Resources!$A$2:$A$64,0))) -> 0 | M11: =B11&"|"&D11&"|"&C11 -> All Power Labs CHP|Electricity|Output
A12: F0011 | B12: All Power Labs CHP | C12: Output | D12: Heat | E12: 950000 | F12: =IFERROR(INDEX(Resources!$B$2:$B$64,MATCH($D12,Resources!$A$2:$A$64,0)),"?") -> BTU | G12: Weekly | H12: =E12*INDEX(Assumptions!$D$17:$D$23,MATCH(G12,Assumptions!$B$17:$B$23,0)) -> 950000 | I12: =IFERROR(INDEX(Systems!$R$2:$R$179,MATCH($B12,Systems!$B$2:$B$179,0)),0) -> 0 | J12: =H12*I12 -> 0 | K12: =IFERROR(IF(INDEX(Resources!$D$2:$D$64,MATCH($D12,Resources!$A$2:$A$64,0))="","",INDEX(Resources!$D$2:$D$64,MATCH($D12,Resources!$A$2:$A$64,0))),"") -> Heated shelter | L12: =IF(K12="","",J12*INDEX(Resources!$E$2:$E$64,MATCH($D12,Resources!$A$2:$A$64,0))) -> 0 | M12: =B12&"|"&D12&"|"&C12 -> All Power Labs CHP|Heat|Output
A13: F0012 | B13: All Power Labs CHP | C13: Output | D13: Biochar | E13: 10 | F13: =IFERROR(INDEX(Resources!$B$2:$B$64,MATCH($D13,Resources!$A$2:$A$64,0)),"?") -> lbs | G13: Weekly | H13: =E13*INDEX(Assumptions!$D$17:$D$23,MATCH(G13,Assumptions!$B$17:$B$23,0)) -> 10 | I13: =IFERROR(INDEX(Systems!$R$2:$R$179,MATCH($B13,Systems!$B$2:$B$179,0)),0) -> 0 | J13: =H13*I13 -> 0 | K13: =IFERROR(IF(INDEX(Resources!$D$2:$D$64,MATCH($D13,Resources!$A$2:$A$64,0))="","",INDEX(Resources!$D$2:$D$64,MATCH($D13,Resources!$A$2:$A$64,0))),"") | L13: =IF(K13="","",J13*INDEX(Resources!$E$2:$E$64,MATCH($D13,Resources!$A$2:$A$64,0))) | M13: =B13&"|"&D13&"|"&C13 -> All Power Labs CHP|Biochar|Output
A14: F0013 | B14: Biochar | C14: Input | D14: Labor | E14: 2 | F14: =IFERROR(INDEX(Resources!$B$2:$B$64,MATCH($D14,Resources!$A$2:$A$64,0)),"?") -> hours | G14: Weekly | H14: =E14*INDEX(Assumptions!$D$17:$D$23,MATCH(G14,Assumptions!$B$17:$B$23,0)) -> 2 | I14: =IFERROR(INDEX(Systems!$R$2:$R$179,MATCH($B14,Systems!$B$2:$B$179,0)),0) -> 0 | J14: =H14*I14 -> 0 | K14: =IFERROR(IF(INDEX(Resources!$D$2:$D$64,MATCH($D14,Resources!$A$2:$A$64,0))="","",INDEX(Resources!$D$2:$D$64,MATCH($D14,Resources!$A$2:$A$64,0))),"") -> Est. Required Labor | L14: =IF(K14="","",J14*INDEX(Resources!$E$2:$E$64,MATCH($D14,Resources!$A$2:$A$64,0))) -> 0 | M14: =B14&"|"&D14&"|"&C14 -> Biochar|Labor|Input | N14: Weekly upkeep hours (Systems column K).
A15: F0014 | B15: Biochar | C15: Input | D15: Woody biomass | E15: 100 | F15: =IFERROR(INDEX(Resources!$B$2:$B$64,MATCH($D15,Resources!$A$2:$A$64,0)),"?") -> lbs | G15: Weekly | H15: =E15*INDEX(Assumptions!$D$17:$D$23,MATCH(G15,Assumptions!$B$17:$B$23,0)) -> 100 | I15: =IFERROR(INDEX(Systems!$R$2:$R$179,MATCH($B15,Systems!$B$2:$B$179,0)),0) -> 0 | J15: =H15*I15 -> 0 | K15: =IFERROR(IF(INDEX(Resources!$D$2:$D$64,MATCH($D15,Resources!$A$2:$A$64,0))="","",INDEX(Resources!$D$2:$D$64,MATCH($D15,Resources!$A$2:$A$64,0))),"") | L15: =IF(K15="","",J15*INDEX(Resources!$E$2:$E$64,MATCH($D15,Resources!$A$2:$A$64,0))) | M15: =B15&"|"&D15&"|"&C15 -> Biochar|Woody biomass|Input
A16: F0015 | B16: Biochar | C16: Input | D16: Water | E16: 20 | F16: =IFERROR(INDEX(Resources!$B$2:$B$64,MATCH($D16,Resources!$A$2:$A$64,0)),"?") -> gal | G16: Weekly | H16: =E16*INDEX(Assumptions!$D$17:$D$23,MATCH(G16,Assumptions!$B$17:$B$23,0)) -> 20 | I16: =IFERROR(INDEX(Systems!$R$2:$R$179,MATCH($B16,Systems!$B$2:$B$179,0)),0) -> 0 | J16: =H16*I16 -> 0 | K16: =IFERROR(IF(INDEX(Resources!$D$2:$D$64,MATCH($D16,Resources!$A$2:$A$64,0))="","",INDEX(Resources!$D$2:$D$64,MATCH($D16,Resources!$A$2:$A$64,0))),"") -> Water | L16: =IF(K16="","",J16*INDEX(Resources!$E$2:$E$64,MATCH($D16,Resources!$A$2:$A$64,0))) -> 0 | M16: =B16&"|"&D16&"|"&C16 -> Biochar|Water|Input
A17: F0016 | B17: Biochar | C17: Output | D17: Biochar | E17: 15 | F17: =IFERROR(INDEX(Resources!$B$2:$B$64,MATCH($D17,Resources!$A$2:$A$64,0)),"?") -> lbs | G17: Weekly | H17: =E17*INDEX(Assumptions!$D$17:$D$23,MATCH(G17,Assumptions!$B$17:$B$23,0)) -> 15 | I17: =IFERROR(INDEX(Systems!$R$2:$R$179,MATCH($B17,Systems!$B$2:$B$179,0)),0) -> 0 | J17: =H17*I17 -> 0 | K17: =IFERROR(IF(INDEX(Resources!$D$2:$D$64,MATCH($D17,Resources!$A$2:$A$64,0))="","",INDEX(Resources!$D$2:$D$64,MATCH($D17,Resources!$A$2:$A$64,0))),"") | L17: =IF(K17="","",J17*INDEX(Resources!$E$2:$E$64,MATCH($D17,Resources!$A$2:$A$64,0))) | M17: =B17&"|"&D17&"|"&C17 -> Biochar|Biochar|Output
A18: F0017 | B18: Biochar Double Barrel Retort | C18: Input | D18: Labor | E18: 2 | F18: =IFERROR(INDEX(Resources!$B$2:$B$64,MATCH($D18,Resources!$A$2:$A$64,0)),"?") -> hours | G18: Weekly | H18: =E18*INDEX(Assumptions!$D$17:$D$23,MATCH(G18,Assumptions!$B$17:$B$23,0)) -> 2 | I18: =IFERROR(INDEX(Systems!$R$2:$R$179,MATCH($B18,Systems!$B$2:$B$179,0)),0) -> 0 | J18: =H18*I18 -> 0 | K18: =IFERROR(IF(INDEX(Resources!$D$2:$D$64,MATCH($D18,Resources!$A$2:$A$64,0))="","",INDEX(Resources!$D$2:$D$64,MATCH($D18,Resources!$A$2:$A$64,0))),"") -> Est. Required Labor | L18: =IF(K18="","",J18*INDEX(Resources!$E$2:$E$64,MATCH($D18,Resources!$A$2:$A$64,0))) -> 0 | M18: =B18&"|"&D18&"|"&C18 -> Biochar Double Barrel Retort|Labor|Input | N18: Weekly upkeep hours (Systems column K).
A19: F0018 | B19: Biochar Double Barrel Retort | C19: Input | D19: Wood chips | E19: 60 | F19: =IFERROR(INDEX(Resources!$B$2:$B$64,MATCH($D19,Resources!$A$2:$A$64,0)),"?") -> lbs | G19: Weekly | H19: =E19*INDEX(Assumptions!$D$17:$D$23,MATCH(G19,Assumptions!$B$17:$B$23,0)) -> 60 | I19: =IFERROR(INDEX(Systems!$R$2:$R$179,MATCH($B19,Systems!$B$2:$B$179,0)),0) -> 0 | J19: =H19*I19 -> 0 | K19: =IFERROR(IF(INDEX(Resources!$D$2:$D$64,MATCH($D19,Resources!$A$2:$A$64,0))="","",INDEX(Resources!$D$2:$D$64,MATCH($D19,Resources!$A$2:$A$64,0))),"") | L19: =IF(K19="","",J19*INDEX(Resources!$E$2:$E$64,MATCH($D19,Resources!$A$2:$A$64,0))) | M19: =B19&"|"&D19&"|"&C19 -> Biochar Double Barrel Retort|Wood chips|Input
A20: F0019 | B20: Biochar Double Barrel Retort | C20: Input | D20: Woody biomass | E20: 40 | F20: =IFERROR(INDEX(Resources!$B$2:$B$64,MATCH($D20,Resources!$A$2:$A$64,0)),"?") -> lbs | G20: Weekly | H20: =E20*INDEX(Assumptions!$D$17:$D$23,MATCH(G20,Assumptions!$B$17:$B$23,0)) -> 40 | I20: =IFERROR(INDEX(Systems!$R$2:$R$179,MATCH($B20,Systems!$B$2:$B$179,0)),0) -> 0 | J20: =H20*I20 -> 0 | K20: =IFERROR(IF(INDEX(Resources!$D$2:$D$64,MATCH($D20,Resources!$A$2:$A$64,0))="","",INDEX(Resources!$D$2:$D$64,MATCH($D20,Resources!$A$2:$A$64,0))),"") | L20: =IF(K20="","",J20*INDEX(Resources!$E$2:$E$64,MATCH($D20,Resources!$A$2:$A$64,0))) | M20: =B20&"|"&D20&"|"&C20 -> Biochar Double Barrel Retort|Woody biomass|Input
A21: F0020 | B21: Biochar Double Barrel Retort | C21: Input | D21: Waste lumber | E21: 20 | F21: =IFERROR(INDEX(Resources!$B$2:$B$64,MATCH($D21,Resources!$A$2:$A$64,0)),"?") -> lbs | G21: Weekly | H21: =E21*INDEX(Assumptions!$D$17:$D$23,MATCH(G21,Assumptions!$B$17:$B$23,0)) -> 20 | I21: =IFERROR(INDEX(Systems!$R$2:$R$179,MATCH($B21,Systems!$B$2:$B$179,0)),0) -> 0 | J21: =H21*I21 -> 0 | K21: =IFERROR(IF(INDEX(Resources!$D$2:$D$64,MATCH($D21,Resources!$A$2:$A$64,0))="","",INDEX(Resources!$D$2:$D$64,MATCH($D21,Resources!$A$2:$A$64,0))),"") | L21: =IF(K21="","",J21*INDEX(Resources!$E$2:$E$64,MATCH($D21,Resources!$A$2:$A$64,0))) | M21: =B21&"|"&D21&"|"&C21 -> Biochar Double Barrel Retort|Waste lumber|Input
A22: F0021 | B22: Biochar Double Barrel Retort | C22: Output | D22: Heat | E22: 60000 | F22: =IFERROR(INDEX(Resources!$B$2:$B$64,MATCH($D22,Resources!$A$2:$A$64,0)),"?") -> BTU | G22: Weekly | H22: =E22*INDEX(Assumptions!$D$17:$D$23,MATCH(G22,Assumptions!$B$17:$B$23,0)) -> 60000 | I22: =IFERROR(INDEX(Systems!$R$2:$R$179,MATCH($B22,Systems!$B$2:$B$179,0)),0) -> 0 | J22: =H22*I22 -> 0 | K22: =IFERROR(IF(INDEX(Resources!$D$2:$D$64,MATCH($D22,Resources!$A$2:$A$64,0))="","",INDEX(Resources!$D$2:$D$64,MATCH($D22,Resources!$A$2:$A$64,0))),"") -> Heated shelter | L22: =IF(K22="","",J22*INDEX(Resources!$E$2:$E$64,MATCH($D22,Resources!$A$2:$A$64,0))) -> 0 | M22: =B22&"|"&D22&"|"&C22 -> Biochar Double Barrel Retort|Heat|Output
A23: F0022 | B23: Biochar Double Barrel Retort | C23: Output | D23: Biochar | E23: 20 | F23: =IFERROR(INDEX(Resources!$B$2:$B$64,MATCH($D23,Resources!$A$2:$A$64,0)),"?") -> lbs | G23: Weekly | H23: =E23*INDEX(Assumptions!$D$17:$D$23,MATCH(G23,Assumptions!$B$17:$B$23,0)) -> 20 | I23: =IFERROR(INDEX(Systems!$R$2:$R$179,MATCH($B23,Systems!$B$2:$B$179,0)),0) -> 0 | J23: =H23*I23 -> 0 | K23: =IFERROR(IF(INDEX(Resources!$D$2:$D$64,MATCH($D23,Resources!$A$2:$A$64,0))="","",INDEX(Resources!$D$2:$D$64,MATCH($D23,Resources!$A$2:$A$64,0))),"") | L23: =IF(K23="","",J23*INDEX(Resources!$E$2:$E$64,MATCH($D23,Resources!$A$2:$A$64,0))) | M23: =B23&"|"&D23&"|"&C23 -> Biochar Double Barrel Retort|Biochar|Output
A24: F0023 | B24: A-Frame House | C24: Input | D24: Labor | E24: 1 | F24: =IFERROR(INDEX(Resources!$B$2:$B$64,MATCH($D24,Resources!$A$2:$A$64,0)),"?") -> hours | G24: Weekly | H24: =E24*INDEX(Assumptions!$D$17:$D$23,MATCH(G24,Assumptions!$B$17:$B$23,0)) -> 1 | I24: =IFERROR(INDEX(Systems!$R$2:$R$179,MATCH($B24,Systems!$B$2:$B$179,0)),0) -> 0 | J24: =H24*I24 -> 0 | K24: =IFERROR(IF(INDEX(Resources!$D$2:$D$64,MATCH($D24,Resources!$A$2:$A$64,0))="","",INDEX(Resources!$D$2:$D$64,MATCH($D24,Resources!$A$2:$A$64,0))),"") -> Est. Required Labor | L24: =IF(K24="","",J24*INDEX(Resources!$E$2:$E$64,MATCH($D24,Resources!$A$2:$A$64,0))) -> 0 | M24: =B24&"|"&D24&"|"&C24 -> A-Frame House|Labor|Input | N24: Weekly upkeep hours (Systems column K).
A25: F0024 | B25: A-Frame House | C25: Input | D25: Capital | E25: 60 | F25: =IFERROR(INDEX(Resources!$B$2:$B$64,MATCH($D25,Resources!$A$2:$A$64,0)),"?") -> $ | G25: Weekly | H25: =E25*INDEX(Assumptions!$D$17:$D$23,MATCH(G25,Assumptions!$B$17:$B$23,0)) -> 60 | I25: =IFERROR(INDEX(Systems!$R$2:$R$179,MATCH($B25,Systems!$B$2:$B$179,0)),0) -> 0 | J25: =H25*I25 -> 0 | K25: =IFERROR(IF(INDEX(Resources!$D$2:$D$64,MATCH($D25,Resources!$A$2:$A$64,0))="","",INDEX(Resources!$D$2:$D$64,MATCH($D25,Resources!$A$2:$A$64,0))),"") | L25: =IF(K25="","",J25*INDEX(Resources!$E$2:$E$64,MATCH($D25,Resources!$A$2:$A$64,0))) | M25: =B25&"|"&D25&"|"&C25 -> A-Frame House|Capital|Input
A26: F0025 | B26: A-Frame House | C26: Output | D26: Shelter | E26: 800 | F26: =IFERROR(INDEX(Resources!$B$2:$B$64,MATCH($D26,Resources!$A$2:$A$64,0)),"?") -> sq ft | G26: Capacity | H26: =E26*INDEX(Assumptions!$D$17:$D$23,MATCH(G26,Assumptions!$B$17:$B$23,0)) -> 800 | I26: =IFERROR(INDEX(Systems!$R$2:$R$179,MATCH($B26,Systems!$B$2:$B$179,0)),0) -> 0 | J26: =H26*I26 -> 0 | K26: =IFERROR(IF(INDEX(Resources!$D$2:$D$64,MATCH($D26,Resources!$A$2:$A$64,0))="","",INDEX(Resources!$D$2:$D$64,MATCH($D26,Resources!$A$2:$A$64,0))),"") -> Shelter | L26: =IF(K26="","",J26*INDEX(Resources!$E$2:$E$64,MATCH($D26,Resources!$A$2:$A$64,0))) -> 0 | M26: =B26&"|"&D26&"|"&C26 -> A-Frame House|Shelter|Output
A27: F0026 | B27: A-Frame House | C27: Output | D27: Roofing area | E27: 1100 | F27: =IFERROR(INDEX(Resources!$B$2:$B$64,MATCH($D27,Resources!$A$2:$A$64,0)),"?") -> sq ft | G27: Capacity | H27: =E27*INDEX(Assumptions!$D$17:$D$23,MATCH(G27,Assumptions!$B$17:$B$23,0)) -> 1100 | I27: =IFERROR(INDEX(Systems!$R$2:$R$179,MATCH($B27,Systems!$B$2:$B$179,0)),0) -> 0 | J27: =H27*I27 -> 0 | K27: =IFERROR(IF(INDEX(Resources!$D$2:$D$64,MATCH($D27,Resources!$A$2:$A$64,0))="","",INDEX(Resources!$D$2:$D$64,MATCH($D27,Resources!$A$2:$A$64,0))),"") | L27: =IF(K27="","",J27*INDEX(Resources!$E$2:$E$64,MATCH($D27,Resources!$A$2:$A$64,0))) | M27: =B27&"|"&D27&"|"&C27 -> A-Frame House|Roofing area|Output
A28: F0027 | B28: A-Frame House | C28: Input | D28: Heat | E28: =INDEX(Systems!$N$2:$N$179,MATCH($B28,Systems!$B$2:$B$179,0))*INDEX(Systems!$O$2:$O$179,MATCH($B28,Systems!$B$2:$B$179,0))*Assumptions!$C$4*24/52 -> 664615.38 | F28: =IFERROR(INDEX(Resources!$B$2:$B$64,MATCH($D28,Resources!$A$2:$A$64,0)),"?") -> BTU | G28: Weekly | H28: =E28*INDEX(Assumptions!$D$17:$D$23,MATCH(G28,Assumptions!$B$17:$B$23,0)) -> 664615.38 | I28: =IFERROR(INDEX(Systems!$R$2:$R$179,MATCH($B28,Systems!$B$2:$B$179,0)),0) -> 0 | J28: =H28*I28 -> 0 | K28: =IFERROR(IF(INDEX(Resources!$D$2:$D$64,MATCH($D28,Resources!$A$2:$A$64,0))="","",INDEX(Resources!$D$2:$D$64,MATCH($D28,Resources!$A$2:$A$64,0))),"") -> Heated shelter | L28: =IF(K28="","",J28*INDEX(Resources!$E$2:$E$64,MATCH($D28,Resources!$A$2:$A$64,0))) -> 0 | M28: =B28&"|"&D28&"|"&C28 -> A-Frame House|Heat|Input | N28: Heating load = area x heat-loss factor x HDD x 24 / 52.
A29: F0028 | B29: A-Frame House | C29: Input | D29: Cooling | E29: =INDEX(Systems!$N$2:$N$179,MATCH($B29,Systems!$B$2:$B$179,0))*INDEX(Systems!$O$2:$O$179,MATCH($B29,Systems!$B$2:$B$179,0))*Assumptions!$C$5*24/52 -> 88615.385 | F29: =IFERROR(INDEX(Resources!$B$2:$B$64,MATCH($D29,Resources!$A$2:$A$64,0)),"?") -> BTU | G29: Weekly | H29: =E29*INDEX(Assumptions!$D$17:$D$23,MATCH(G29,Assumptions!$B$17:$B$23,0)) -> 88615.385 | I29: =IFERROR(INDEX(Systems!$R$2:$R$179,MATCH($B29,Systems!$B$2:$B$179,0)),0) -> 0 | J29: =H29*I29 -> 0 | K29: =IFERROR(IF(INDEX(Resources!$D$2:$D$64,MATCH($D29,Resources!$A$2:$A$64,0))="","",INDEX(Resources!$D$2:$D$64,MATCH($D29,Resources!$A$2:$A$64,0))),"") -> Cooled shelter | L29: =IF(K29="","",J29*INDEX(Resources!$E$2:$E$64,MATCH($D29,Resources!$A$2:$A$64,0))) -> 0 | M29: =B29&"|"&D29&"|"&C29 -> A-Frame House|Cooling|Input | N29: Cooling load = area x heat-loss factor x CDD x 24 / 52.
A30: F0029 | B30: Average Suburban Home | C30: Input | D30: Labor | E30: 2 | F30: =IFERROR(INDEX(Resources!$B$2:$B$64,MATCH($D30,Resources!$A$2:$A$64,0)),"?") -> hours | G30: Weekly | H30: =E30*INDEX(Assumptions!$D$17:$D$23,MATCH(G30,Assumptions!$B$17:$B$23,0)) -> 2 | I30: =IFERROR(INDEX(Systems!$R$2:$R$179,MATCH($B30,Systems!$B$2:$B$179,0)),0) -> 0 | J30: =H30*I30 -> 0 | K30: =IFERROR(IF(INDEX(Resources!$D$2:$D$64,MATCH($D30,Resources!$A$2:$A$64,0))="","",INDEX(Resources!$D$2:$D$64,MATCH($D30,Resources!$A$2:$A$64,0))),"") -> Est. Required Labor | L30: =IF(K30="","",J30*INDEX(Resources!$E$2:$E$64,MATCH($D30,Resources!$A$2:$A$64,0))) -> 0 | M30: =B30&"|"&D30&"|"&C30 -> Average Suburban Home|Labor|Input | N30: Weekly upkeep hours (Systems column K).
A31: F0030 | B31: Average Suburban Home | C31: Input | D31: Capital | E31: 250 | F31: =IFERROR(INDEX(Resources!$B$2:$B$64,MATCH($D31,Resources!$A$2:$A$64,0)),"?") -> $ | G31: Weekly | H31: =E31*INDEX(Assumptions!$D$17:$D$23,MATCH(G31,Assumptions!$B$17:$B$23,0)) -> 250 | I31: =IFERROR(INDEX(Systems!$R$2:$R$179,MATCH($B31,Systems!$B$2:$B$179,0)),0) -> 0 | J31: =H31*I31 -> 0 | K31: =IFERROR(IF(INDEX(Resources!$D$2:$D$64,MATCH($D31,Resources!$A$2:$A$64,0))="","",INDEX(Resources!$D$2:$D$64,MATCH($D31,Resources!$A$2:$A$64,0))),"") | L31: =IF(K31="","",J31*INDEX(Resources!$E$2:$E$64,MATCH($D31,Resources!$A$2:$A$64,0))) | M31: =B31&"|"&D31&"|"&C31 -> Average Suburban Home|Capital|Input
A32: F0031 | B32: Average Suburban Home | C32: Output | D32: Shelter | E32: 2000 | F32: =IFERROR(INDEX(Resources!$B$2:$B$64,MATCH($D32,Resources!$A$2:$A$64,0)),"?") -> sq ft | G32: Capacity | H32: =E32*INDEX(Assumptions!$D$17:$D$23,MATCH(G32,Assumptions!$B$17:$B$23,0)) -> 2000 | I32: =IFERROR(INDEX(Systems!$R$2:$R$179,MATCH($B32,Systems!$B$2:$B$179,0)),0) -> 0 | J32: =H32*I32 -> 0 | K32: =IFERROR(IF(INDEX(Resources!$D$2:$D$64,MATCH($D32,Resources!$A$2:$A$64,0))="","",INDEX(Resources!$D$2:$D$64,MATCH($D32,Resources!$A$2:$A$64,0))),"") -> Shelter | L32: =IF(K32="","",J32*INDEX(Resources!$E$2:$E$64,MATCH($D32,Resources!$A$2:$A$64,0))) -> 0 | M32: =B32&"|"&D32&"|"&C32 -> Average Suburban Home|Shelter|Output
A33: F0032 | B33: Average Suburban Home | C33: Output | D33: Roofing area | E33: 2200 | F33: =IFERROR(INDEX(Resources!$B$2:$B$64,MATCH($D33,Resources!$A$2:$A$64,0)),"?") -> sq ft | G33: Capacity | H33: =E33*INDEX(Assumptions!$D$17:$D$23,MATCH(G33,Assumptions!$B$17:$B$23,0)) -> 2200 | I33: =IFERROR(INDEX(Systems!$R$2:$R$179,MATCH($B33,Systems!$B$2:$B$179,0)),0) -> 0 | J33: =H33*I33 -> 0 | K33: =IFERROR(IF(INDEX(Resources!$D$2:$D$64,MATCH($D33,Resources!$A$2:$A$64,0))="","",INDEX(Resources!$D$2:$D$64,MATCH($D33,Resources!$A$2:$A$64,0))),"") | L33: =IF(K33="","",J33*INDEX(Resources!$E$2:$E$64,MATCH($D33,Resources!$A$2:$A$64,0))) | M33: =B33&"|"&D33&"|"&C33 -> Average Suburban Home|Roofing area|Output
A34: F0033 | B34: Average Suburban Home | C34: Output | D34: Water | E34: 600 | F34: =IFERROR(INDEX(Resources!$B$2:$B$64,MATCH($D34,Resources!$A$2:$A$64,0)),"?") -> gal | G34: Weekly | H34: =E34*INDEX(Assumptions!$D$17:$D$23,MATCH(G34,Assumptions!$B$17:$B$23,0)) -> 600 | I34: =IFERROR(INDEX(Systems!$R$2:$R$179,MATCH($B34,Systems!$B$2:$B$179,0)),0) -> 0 | J34: =H34*I34 -> 0 | K34: =IFERROR(IF(INDEX(Resources!$D$2:$D$64,MATCH($D34,Resources!$A$2:$A$64,0))="","",INDEX(Resources!$D$2:$D$64,MATCH($D34,Resources!$A$2:$A$64,0))),"") -> Water | L34: =IF(K34="","",J34*INDEX(Resources!$E$2:$E$64,MATCH($D34,Resources!$A$2:$A$64,0))) -> 0 | M34: =B34&"|"&D34&"|"&C34 -> Average Suburban Home|Water|Output
A35: F0034 | B35: Average Suburban Home | C35: Output | D35: Drinking water | E35: 20 | F35: =IFERROR(INDEX(Resources!$B$2:$B$64,MATCH($D35,Resources!$A$2:$A$64,0)),"?") -> gal | G35: Weekly | H35: =E35*INDEX(Assumptions!$D$17:$D$23,MATCH(G35,Assumptions!$B$17:$B$23,0)) -> 20 | I35: =IFERROR(INDEX(Systems!$R$2:$R$179,MATCH($B35,Systems!$B$2:$B$179,0)),0) -> 0 | J35: =H35*I35 -> 0 | K35: =IFERROR(IF(INDEX(Resources!$D$2:$D$64,MATCH($D35,Resources!$A$2:$A$64,0))="","",INDEX(Resources!$D$2:$D$64,MATCH($D35,Resources!$A$2:$A$64,0))),"") -> Drinking water | L35: =IF(K35="","",J35*INDEX(Resources!$E$2:$E$64,MATCH($D35,Resources!$A$2:$A$64,0))) -> 0 | M35: =B35&"|"&D35&"|"&C35 -> Average Suburban Home|Drinking water|Output
A36: F0035 | B36: Average Suburban Home | C36: Output | D36: Hot water | E36: 150 | F36: =IFERROR(INDEX(Resources!$B$2:$B$64,MATCH($D36,Resources!$A$2:$A$64,0)),"?") -> gal | G36: Weekly | H36: =E36*INDEX(Assumptions!$D$17:$D$23,MATCH(G36,Assumptions!$B$17:$B$23,0)) -> 150 | I36: =IFERROR(INDEX(Systems!$R$2:$R$179,MATCH($B36,Systems!$B$2:$B$179,0)),0) -> 0 | J36: =H36*I36 -> 0 | K36: =IFERROR(IF(INDEX(Resources!$D$2:$D$64,MATCH($D36,Resources!$A$2:$A$64,0))="","",INDEX(Resources!$D$2:$D$64,MATCH($D36,Resources!$A$2:$A$64,0))),"") | L36: =IF(K36="","",J36*INDEX(Resources!$E$2:$E$64,MATCH($D36,Resources!$A$2:$A$64,0))) | M36: =B36&"|"&D36&"|"&C36 -> Average Suburban Home|Hot water|Output
A37: F0036 | B37: Average Suburban Home | C37: Output | D37: Sanitation | E37: 35 | F37: =IFERROR(INDEX(Resources!$B$2:$B$64,MATCH($D37,Resources!$A$2:$A$64,0)),"?") -> lbs | G37: Weekly | H37: =E37*INDEX(Assumptions!$D$17:$D$23,MATCH(G37,Assumptions!$B$17:$B$23,0)) -> 35 | I37: =IFERROR(INDEX(Systems!$R$2:$R$179,MATCH($B37,Systems!$B$2:$B$179,0)),0) -> 0 | J37: =H37*I37 -> 0 | K37: =IFERROR(IF(INDEX(Resources!$D$2:$D$64,MATCH($D37,Resources!$A$2:$A$64,0))="","",INDEX(Resources!$D$2:$D$64,MATCH($D37,Resources!$A$2:$A$64,0))),"") -> Sanitation | L37: =IF(K37="","",J37*INDEX(Resources!$E$2:$E$64,MATCH($D37,Resources!$A$2:$A$64,0))) -> 0 | M37: =B37&"|"&D37&"|"&C37 -> Average Suburban Home|Sanitation|Output
A38: F0037 | B38: Average Suburban Home | C38: Input | D38: Heat | E38: =INDEX(Systems!$N$2:$N$179,MATCH($B38,Systems!$B$2:$B$179,0))*INDEX(Systems!$O$2:$O$179,MATCH($B38,Systems!$B$2:$B$179,0))*Assumptions!$C$4*24/52 -> 1384615.4 | F38: =IFERROR(INDEX(Resources!$B$2:$B$64,MATCH($D38,Resources!$A$2:$A$64,0)),"?") -> BTU | G38: Weekly | H38: =E38*INDEX(Assumptions!$D$17:$D$23,MATCH(G38,Assumptions!$B$17:$B$23,0)) -> 1384615.4 | I38: =IFERROR(INDEX(Systems!$R$2:$R$179,MATCH($B38,Systems!$B$2:$B$179,0)),0) -> 0 | J38: =H38*I38 -> 0 | K38: =IFERROR(IF(INDEX(Resources!$D$2:$D$64,MATCH($D38,Resources!$A$2:$A$64,0))="","",INDEX(Resources!$D$2:$D$64,MATCH($D38,Resources!$A$2:$A$64,0))),"") -> Heated shelter | L38: =IF(K38="","",J38*INDEX(Resources!$E$2:$E$64,MATCH($D38,Resources!$A$2:$A$64,0))) -> 0 | M38: =B38&"|"&D38&"|"&C38 -> Average Suburban Home|Heat|Input | N38: Heating load = area x heat-loss factor x HDD x 24 / 52.
